Traceback (most recent call last):
  File "C:\Users\vegag\AppData\Local\Packages\PythonSoftwareFoundation.Python.3.9_qbz5n2kfra8p0\LocalCache\local-packages\Python39\site-packages\wandb\sdk\wandb_config.py", line 162, in __getattr__
    return self.__getitem__(key)
  File "C:\Users\vegag\AppData\Local\Packages\PythonSoftwareFoundation.Python.3.9_qbz5n2kfra8p0\LocalCache\local-packages\Python39\site-packages\wandb\sdk\wandb_config.py", line 130, in __getitem__
    return self._items[key]
KeyError: 'alph'
The above exception was the direct cause of the following exception:
Traceback (most recent call last):
  File "D:\GithubProject\mcv-c6-2024-team3\Week1\optimization_task1_1.py", line 44, in train
    modelo.fast_test(alpha=config.alph, kernel_size=(kernel_number, kernel_number))
  File "C:\Users\vegag\AppData\Local\Packages\PythonSoftwareFoundation.Python.3.9_qbz5n2kfra8p0\LocalCache\local-packages\Python39\site-packages\wandb\sdk\wandb_config.py", line 164, in __getattr__
    raise AttributeError(
AttributeError: <class 'wandb.sdk.wandb_config.Config'> object has no attribute 'alph'